# 종합문제
## Q12 오류와 예외 처리
다음 코드의 실행 결과를 예측하고 그 이유에 대해 설명하시오.
```python
result = 0
try:
    [1,2,3][3]
    "a"+1
    4/0
except TypeError:
    result+=1
except ZeroDivisionError:
    result+=2
except IndexError:
    result+=3
finally:
    result+=4
print(result)
7
```
최초에 발생한 오류는 [1,2,3][3]로 IndexError가 발생한다. 따라서 result에 3이 더해져 3이된다. 최종적으로 finally에 의해  result에 4가 더해져 7이된다. 따라서 7이 출력된다.